{"timestamp": "2025-05-13T19:54:10.058448", "level": "CRITICAL", "message": "Failed to initialize application: (psycopg2.OperationalError) connection to server at \"localhost\" (::1), port 5432 failed: Connection refused (0x0000274D/10061)\n\tIs the server running on that host and accepting TCP/IP connections?\nconnection to server at \"localhost\" (127.0.0.1), port 5432 failed: Connection refused (0x0000274D/10061)\n\tIs the server running on that host and accepting TCP/IP connections?\n\n(Background on this error at: https://sqlalche.me/e/20/e3q8)", "module": "__init__", "function": "create_app", "line": 58, "process": 10852, "thread": "MainThread"}
{"timestamp": "2025-05-13T20:32:46.600393", "level": "INFO", "message": "Database tables initialized", "module": "__init__", "function": "create_app", "line": 47, "process": 13800, "thread": "MainThread"}
{"timestamp": "2025-05-13T20:33:45.317683", "level": "INFO", "message": "Database connection established", "module": "db_handler", "function": "_init_db", "line": 26, "process": 13800, "thread": "MainThread"}
{"timestamp": "2025-05-13T20:33:45.318253", "level": "INFO", "message": "Database connection established", "module": "db_handler", "function": "_init_db", "line": 26, "process": 13800, "thread": "MainThread"}
{"timestamp": "2025-05-13T20:33:49.118264", "level": "INFO", "message": "Application initialized successfully", "module": "__init__", "function": "create_app", "line": 54, "process": 13800, "thread": "MainThread"}
{"timestamp": "2025-05-13T20:33:55.026394", "level": "WARNING", "message": "Not found: 404 Not Found: The requested URL was not found on the server. If you entered the URL manually please check your spelling and try again.", "module": "__init__", "function": "not_found", "line": 74, "process": 13800, "thread": "Thread-2 (process_request_thread)"}
{"timestamp": "2025-05-13T21:29:56.457279", "level": "WARNING", "message": "Not found: 404 Not Found: The requested URL was not found on the server. If you entered the URL manually please check your spelling and try again.", "module": "__init__", "function": "not_found", "line": 74, "process": 13800, "thread": "Thread-3 (process_request_thread)"}
{"timestamp": "2025-05-13T21:30:17.544639", "level": "ERROR", "message": "Twilio API error: \n\u001b[31m\u001b[49mHTTP Error\u001b[0m \u001b[37m\u001b[49mYour request was:\u001b[0m\n\n\u001b[36m\u001b[49mPOST /Accounts/AC3b33ee1708fe8dd88ed7356b4867b515/Calls.json\u001b[0m\n\n\u001b[37m\u001b[49mTwilio returned the following information:\u001b[0m\n\n\u001b[34m\u001b[49mUnable to create record: The number +923363957682 is unverified. Trial accounts may only make calls to verified numbers.\u001b[0m\n\n\u001b[37m\u001b[49mMore information may be available here:\u001b[0m\n\n\u001b[34m\u001b[49mhttps://www.twilio.com/docs/errors/21219\u001b[0m\n\n", "module": "routes", "function": "initiate_call", "line": 436, "process": 13800, "thread": "Thread-4 (process_request_thread)"}
{"timestamp": "2025-05-13T21:30:17.546936", "level": "ERROR", "message": "Twilio API error: \n\u001b[31m\u001b[49mHTTP Error\u001b[0m \u001b[37m\u001b[49mYour request was:\u001b[0m\n\n\u001b[36m\u001b[49mPOST /Accounts/AC3b33ee1708fe8dd88ed7356b4867b515/Calls.json\u001b[0m\n\n\u001b[37m\u001b[49mTwilio returned the following information:\u001b[0m\n\n\u001b[34m\u001b[49mUnable to create record: The number +923363957682 is unverified. Trial accounts may only make calls to verified numbers.\u001b[0m\n\n\u001b[37m\u001b[49mMore information may be available here:\u001b[0m\n\n\u001b[34m\u001b[49mhttps://www.twilio.com/docs/errors/21219\u001b[0m\n\n", "module": "routes", "function": "initiate_call", "line": 436, "process": 13800, "thread": "Thread-4 (process_request_thread)"}
{"timestamp": "2025-05-13T21:44:04.238401", "level": "INFO", "message": "Database tables initialized", "module": "__init__", "function": "create_app", "line": 47, "process": 1388, "thread": "MainThread"}
{"timestamp": "2025-05-13T21:44:16.020514", "level": "INFO", "message": "Database connection established", "module": "db_handler", "function": "_init_db", "line": 26, "process": 1388, "thread": "MainThread"}
{"timestamp": "2025-05-13T21:44:16.021179", "level": "INFO", "message": "Database connection established", "module": "db_handler", "function": "_init_db", "line": 26, "process": 1388, "thread": "MainThread"}
{"timestamp": "2025-05-13T21:44:18.046021", "level": "INFO", "message": "Application initialized successfully", "module": "__init__", "function": "create_app", "line": 54, "process": 1388, "thread": "MainThread"}
{"timestamp": "2025-05-13T21:44:20.209889", "level": "WARNING", "message": "Not found: 404 Not Found: The requested URL was not found on the server. If you entered the URL manually please check your spelling and try again.", "module": "__init__", "function": "not_found", "line": 74, "process": 1388, "thread": "Thread-2 (process_request_thread)"}
{"timestamp": "2025-05-13T21:44:28.648165", "level": "WARNING", "message": "Not found: 404 Not Found: The requested URL was not found on the server. If you entered the URL manually please check your spelling and try again.", "module": "__init__", "function": "not_found", "line": 74, "process": 1388, "thread": "Thread-4 (process_request_thread)"}
{"timestamp": "2025-05-13T21:44:53.548097", "level": "ERROR", "message": "Twilio API error: \n\u001b[31m\u001b[49mHTTP Error\u001b[0m \u001b[37m\u001b[49mYour request was:\u001b[0m\n\n\u001b[36m\u001b[49mPOST /Accounts/AC3b33ee1708fe8dd88ed7356b4867b515/Calls.json\u001b[0m\n\n\u001b[37m\u001b[49mTwilio returned the following information:\u001b[0m\n\n\u001b[34m\u001b[49mUnable to create record: Account not authorized to call +923132789418. Perhaps you need to enable some international permissions: https://www.twilio.com/console/voice/calls/geo-permissions/low-risk\u001b[0m\n\n\u001b[37m\u001b[49mMore information may be available here:\u001b[0m\n\n\u001b[34m\u001b[49mhttps://www.twilio.com/docs/errors/21215\u001b[0m\n\n", "module": "routes", "function": "initiate_call", "line": 436, "process": 1388, "thread": "Thread-5 (process_request_thread)"}
{"timestamp": "2025-05-13T21:44:53.550533", "level": "ERROR", "message": "Twilio API error: \n\u001b[31m\u001b[49mHTTP Error\u001b[0m \u001b[37m\u001b[49mYour request was:\u001b[0m\n\n\u001b[36m\u001b[49mPOST /Accounts/AC3b33ee1708fe8dd88ed7356b4867b515/Calls.json\u001b[0m\n\n\u001b[37m\u001b[49mTwilio returned the following information:\u001b[0m\n\n\u001b[34m\u001b[49mUnable to create record: Account not authorized to call +923132789418. Perhaps you need to enable some international permissions: https://www.twilio.com/console/voice/calls/geo-permissions/low-risk\u001b[0m\n\n\u001b[37m\u001b[49mMore information may be available here:\u001b[0m\n\n\u001b[34m\u001b[49mhttps://www.twilio.com/docs/errors/21215\u001b[0m\n\n", "module": "routes", "function": "initiate_call", "line": 436, "process": 1388, "thread": "Thread-5 (process_request_thread)"}
